Workbook

Sheet Price DE
A1: # | B1: Ihr Preis EUR (Amazon verkaufen, DE) | D1: Angebotspreis EUR (-4,00 EUR) | E1: Listenpreis (UVP) EUR (Netto, +25%) | F1: Listenpreis mit Steuern EUR (Brutto, 19% MwSt) | G1: Zulässiger Mindestpreis EUR (-5% vom Angebot) | H1: Maximaler Verkäuferpreis EUR (+10% vom Ihr Preis) | I1: Amazon Business B2B EUR (-3% für Buy Box) | J1: Zulässiger Mindestpreis B2B EUR (−5% vom B2B) | K1: Maximaler Verkäuferpreis B2B EUR (+10% vom B2B)
A2: 1 | B2: 399.99 | C2: CH970-BLK | D2: 395.99 | E2: 420.16 | F2: 499.99 | G2: 376.19 | H2: 439.99 | I2: 384.11 | J2: 364.9 | K2: 422.52
A3: 2 | B3: 419.99 | C3: CH970-GREY | D3: 415.99 | E3: 441.17 | F3: 524.99 | G3: 395.19 | H3: 461.99 | I3: 403.51 | J3: 383.33 | K3: 443.86
A4: 3 | B4: 259.99 | C4: CH980-BLK | D4: 255.99 | E4: 273.1 | F4: 324.99 | G4: 243.19 | H4: 285.99 | I4: 248.31 | J4: 235.89 | K4: 273.14
A5: 4 | B5: 269.99 | C5: CH980-GREY | D5: 265.99 | E5: 283.6 | F5: 337.49 | G5: 252.69 | H5: 296.99 | I5: 258.01 | J5: 245.11 | K5: 283.81
A6: 5 | B6: 289.99 | C6: CH975-BLK | D6: 285.99 | E6: 304.61 | F6: 362.49 | G6: 271.69 | H6: 318.99 | I6: 277.41 | J6: 263.54 | K6: 305.15
A7: 6 | B7: 309.99 | C7: CH975-GREY | D7: 305.99 | E7: 325.62 | F7: 387.49 | G7: 290.69 | H7: 340.99 | I7: 296.81 | J7: 281.97 | K7: 326.49
A8: 7 | B8: 259.99 | C8: CH980-BLK | D8: 255.99 | E8: 273.1 | F8: 324.99 | G8: 243.19 | H8: 285.99 | I8: 248.31 | J8: 235.89 | K8: 273.14
A9: 8 | B9: 269.99 | C9: CH980-GREY | D9: 265.99 | E9: 283.6 | F9: 337.49 | G9: 252.69 | H9: 296.99 | I9: 258.01 | J9: 245.11 | K9: 283.81
A10: 9 | B10: 289.99 | C10: CH975-BLK | D10: 285.99 | E10: 304.61 | F10: 362.49 | G10: 271.69 | H10: 318.99 | I10: 277.41 | J10: 263.54 | K10: 305.15
A11: 10 | B11: 309.99 | C11: CH975-GREY | D11: 305.99 | E11: 325.62 | F11: 387.49 | G11: 290.69 | H11: 340.99 | I11: 296.81 | J11: 281.97 | K11: 326.49
A12: 11 | B12: 399.99 | C12: CH970-BLK | D12: 395.99 | E12: 420.16 | F12: 499.99 | G12: 376.19 | H12: 439.99 | I12: 384.11 | J12: 364.9 | K12: 422.52
A13: 12 | B13: 419.99 | C13: CH970-GREY | D13: 415.99 | E13: 441.17 | F13: 524.99 | G13: 395.19 | H13: 461.99 | I13: 403.51 | J13: 383.33 | K13: 443.86
B15: Angebotspreis = Ihr Preis − 4 € (в рамках заданных 3–5 €)
B16: UVP Netto = (Ihr Preis / 1,19) × 1,25 — Netto-база + 25% маржинальности
B17: UVP Brutto = UVP Netto × 1,19 — обратно с 19% MwSt
B18: Mindestpreis = 95% от Angebotspreis (нижний floor)
B19: Maximalpreis = 110% от Ihr Preis (верхний ceiling)
B20: B2B = 97% от Angebotspreis (снижение на 3% для захвата Buy Box)
B21: Zulässiger Mindestpreis B2B = B2B-Preis × 0,95 (−5% от Business-цены, нижний floor)
B22: Maximaler Verkäuferpreis B2B = B2B-Preis × 1,10 (+10% к Business-цене, верхний ceiling)
B24: Столбец | D24: Формула | E24: Логика
B25: **Ihr Preis EUR** | D25: Исходные данные | E25: Ваши текущие цены (вкл. 19% MwSt)
B26: **Angebotspreis EUR** | D26: `=Ihr Preis − 4,00` | E26: На 4 евро ниже (в диапазоне 3–5 €)
B27: **Listenpreis (UVP) EUR** | D27: `=Ihr Preis / 1.19 × 1.25` | E27: Netto-UVP на 25% выше базовой цены
B28: **Listenpreis mit Steuern EUR** | D28: `=UVP × 1.19` | E28: Brutto-UVP с НДС 19%
B29: **Zulässiger Mindestpreis** | D29: `=Angebotspreis × 0.95` | E29: −5% от акционной цены
B30: **Maximaler Verkäuferpreis** | D30: `=Ihr Preis × 1.10` | E30: =+10% к текущей цене -> #ERROR!
B31: **Amazon Business B2B EUR** | D31: `=Angebotspreis × 0.97` | E31: −3% для конкурентоспособности в Buy Box

Sheet Лист3
B2: Amazon.de Preiskalkulation
B4: Preisgestaltung für Amazon Seller Central (Bei Amazon verkaufen, DE)
B6: Zusammenfassung
B7: Anzahl der Produkte: | D7: 12
B8: MwSt-Satz (DE): | D8: 0.19
B9: Angebotspreis-Rabatt: | D9: 4,00 EUR unter Ihr Preis
B10: UVP-Aufschlag: | D10: 25% über Netto-Ihr Preis
B11: B2B-Rabatt: | D11: 3% unter Angebotspreis (Buy Box-optimiert)
B13: Blattübersicht
B14: Blattname | C14: Beschreibung
B15: Preiskalkulation | C15: Detaillierte Preis berechnungen mit Formeln
B17: Hinweise:
B18: • Alle Preise sind in EUR. • Ihr Preis: Bruttopreis inkl. 19% MwSt (Standard bei Amazon.de). • Angebotspreis: Um 4 EUR reduziert für Werbeaktionen. • B2B-Preis: Mit 3% Rabatt für Amazon Business Buy Box-Optimierung.

Sheet SKU-ASIN
A1: AMAZON DE FBA — МАСТЕР SKU
A3: SKU | B3: ASIN | C3: Название | D3: FBA fee, €/ед | E3: Storage, €/мес/ед | F3: COGS landed, €/ед | G3: Доставка 3PL→FBA, €/ед | H3: Полная COGS, €/ед | I3: TACOS план/факт, %
A4: CH970-GREY | B4: B0D8PFB4VR | C4: SkyLand Bürostuhl Ergonomisch — Grey | D4: 16.85 | E4: 0 | F4: 112.32 | G4: 19.99 | H4: =F4+G4 -> 132.31 | I4: 0.15
A5: CH970-BLK | B5: B0D8PGVY5V | C5: SkyLand Bürostuhl Ergonomisch — Black | D5: 15.98 | E5: 5.55 | F5: 99 | G5: 19.99 | H5: =F5+G5 -> 118.99 | I5: 0.15
A6: CH975-GREY | B6: B0FPCHVY23 | C6: SkyLand Bürostuhl Ergonomisch — Grey (975) | D6: 30.02 | E6: 4.24 | F6: 73.21 | G6: 5.04 | H6: =F6+G6 -> 78.25 | I6: 0.15
A7: CH975-BLK | B7: B0FPCK6XPN | C7: SkyLand Bürostuhl Ergonomisch — Black (975) | D7: 30.02 | E7: 4.24 | F7: 66.56 | G7: 5.04 | H7: =F7+G7 -> 71.6 | I7: 0.15
A8: CH980-GREY | B8: B0FPCK3ZQ2 | C8: SkyLand Bürostuhl Ergonomisch — Grey (980) | D8: 32.64 | E8: 4.73 | F8: 57.41 | G8: 5.04 | H8: =F8+G8 -> 62.45 | I8: 0.15
A9: CH980-BLK | B9: B0FPCK9QZS | C9: SkyLand Bürostuhl Ergonomisch — Black (980) | D9: 32.64 | E9: 4.73 | F9: 53.25 | G9: 5.04 | H9: =F9+G9 -> 58.29 | I9: 0.15
A12: Цвета:
A13: Hardcoded input (синий)
A14: Формула (чёрный)
A15: Ссылка на другой лист (зелёный)
A17: ПРИМЕЧАНИЯ:
A18: • COGS landed взят из Amazon Revenue Calculator (DOC), без НДС.
A19: • Полная COGS = COGS landed + Доставка 3PL → FBA. Обновляйте G под текущий склад FBA.
A20: • TACOS — план 15%, замените на фактический из Amazon Ads.
A21: • FBA fee и Storage — из Amazon Revenue Calculator по каждому ASIN.

Sheet Inputs
A1: ПАРАМЕТРЫ / ASSUMPTIONS
A3: Параметр | B3: Значение | C3: Комментарий
A4: VAT (НДС Германии) | B4: 0.19 | C4: Стандартная ставка Германии 19%
A5: Customs Duty (таможенная пошлина) | B5: 0.05 | C5: 5% для мебели
A6: EPR (экологический сбор), €/год | B6: 399 | C6: Единоразовый годовой
A7: Курс USD → EUR | B7: 0.953 | C7: Курс из исходного файла
A8: Доставка Гонконг → Гамбург, USD/ед | B8: 12.27 | C8: Из исходной модели
A9: Returns / Loss, % | B9: 0.08 | C9: Резерв на возвраты
A10: Скидка Business Price (B2B), % | B10: 0 | C10: B2B всегда ниже Sale Price автоматически (минус VAT). Здесь — ДОП.скидка к net-цене.
A11: Скидка за 2 шт, % | B11: 0.05 | C11: Quantity Discount Tier 1
A12: Скидка за 4 шт, % | B12: 0.07 | C12: Quantity Discount Tier 2
A13: Скидка за 6 шт, % | B13: 0.1 | C13: Quantity Discount Tier 3
A14: Купон — размер скидки, % | B14: 0.1 | C14: Скидка по купону
A15: Купон — variable fee, % выручки | B15: 0.025 | C15: С июня 2025: 2.5% от купонной выручки (per unit)
... A23: Referral fee — порог цены, € | B23: 200 | C23: До €200 → 15%, выше → 10%
A24: Referral fee — % до порога | B24: 0.15
A25: Referral fee — % после порога | B25: 0.1
A26: Referral fee — минимум, € | B26: 0.3 | C26: Минимум на единицу
A27: Корпоративный налог Эстонии, % | B27: 0 | C27: Эстония: 0% на нераспределённую прибыль. 22% (с 2025) при распределении дивидендов. Если ставите 22% — введите 0.22.
A28: Доля прибыли, идущая на дивиденды, % | B28: 0 | C28: 0% = ничего не распределяется → налог 0%. Если 100% распределяется → налог = ставка × 100% прибыли.
A29: % input VAT reclaimable на COGS | B29: 1 | C29: Customs VAT 19% на импорт — обычно 100% возмещаем при наличии VAT-номера в Германии
A30: % input VAT reclaimable на Amazon fees | B30: 1 | C30: При Reverse Charge для EU-сейлеров VAT нетится. Оставьте 100% (нейтрально).
A31: Сертификация (one-time), € | B31: 0
A32: Подготовка инфраструктуры (one-time), € | B32: 0
A33: Прочие постоянные расходы/мес, € | B33: 0 | C33: Бухгалтер, подписки, лицензия MISA если применимо
A36: ПРИМЕЧАНИЯ ПО НАЛОГАМ И FEE:
A37: • Referral fee для DE: ≤€200 → 15%, >€200 → 10% (мин €0.30/ед). Проверено по Amazon DOC.
A38: • Купон с июня 2025: $5 flat + 2.5% от купонной выручки (заменяет старый €0.60/выкуп).
A39: • Deal: с ноября 2025 / 2026 Германия = variable rate ~1.5%, capped at €300/deal.
A40: • PED (Prime Exclusive Discount): вне событий — БЕСПЛАТНО. На Prime Day / BFCM — €100/кампанию (списывается, если есть хотя бы 1 продажа).
A41: • Estonia 0%: если прибыль реинвестируется. 22% применяется только к распределяемым дивидендам.
A42: • ВНИМАНИЕ: хранение товара на FBA в Германии может квалифицироваться как 'постоянное представительство' → ~15.825% корп.налог Германии на часть прибыли. Уточняйте у налогового консультанта.
A43: • VAT: Output VAT собирается с продаж B2C (Amazon собирает с клиента). Input VAT (customs 19% на импорт) возмещается через VAT-возврат Германии.

Sheet Calculator
A1: КАЛЬКУЛЯТОР AMAZON DE — P&L по ценовым уровням
A2: Тарифы: B2C-RRP (Базовый / Купон / Deal / Prime Excl.), Business (B2B), 2/4/6 шт.
A4: SKU | B4: ASIN | C4: Ценовой тариф | D4: Сценарий | E4: RRP с VAT, € | F4: Эфф. цена с VAT, € | G4: Цена без VAT, € | H4: Купон fee на ед, € | I4: Deal fee на ед, € | J4: Referral fee, € | K4: FBA fee, € | L4: Storage fee/ед, € | M4: Реклама (TACOS), € | N4: Резерв возвратов, € | O4: COGS полная, € | P4: Маржа на ед без VAT, € | Q4: Маржа, % | R4: Break-even цена (с VAT), € | S4: ROI на ед, %
A5: CH970-GREY | B5: =VLOOKUP(A5,'SKU-ASIN'!$A$4:$I$9,2,FALSE()) -> B0D8PFB4VR | C5: RRP B2C | D5: Базовый | E5: 415.99 | F5: =E5 -> 415.99 | G5: =F5/(1+Inputs!$B$4) -> 349.57143 | H5: =0 -> 0 | I5: =0 -> 0 | J5: =MAX(Inputs!$B$26,IF(F5<=Inputs!$B$23,F5*Inputs!$B$24,Inputs!$B$23*Inputs!$B$24+(F5-Inputs!$B$23)*Inputs!$B$25)) -> 51.599 | K5: ='SKU-ASIN'!$D$4 -> 16.85 | L5: ='SKU-ASIN'!$E$4 -> 0 | M5: =F5*'SKU-ASIN'!$I$4 -> 62.3985 | N5: =G5*Inputs!$B$9 -> 27.965714 | O5: ='SKU-ASIN'!$H$4 -> 132.31 | P5: =G5-J5-K5-L5-M5-N5-I5-H5-O5 -> 58.448214 | Q5: =IFERROR(P5/G5,0) -> 0.16719963 | R5: =IF(((K5+L5+O5)/(1/(1+Inputs!$B$4)-Inputs!$B$24-'SKU-ASIN'!$I$4-Inputs!$B$9/(1+Inputs!$B$4)))<=Inputs!$B$23,((K5+L5+O5)/(1/(1+Inputs!$B$4)-Inputs!$B$24-'SKU-ASIN'!$I$4-Inputs!$B$9/(1+Inputs!$B$4))),((K5+L5+O5+Inputs!$B$23*(Inputs!$B$24-Inputs!$B$25))/(1/(1+Inputs!$B$4)-Inputs!$B$25-'SKU-ASIN'!$I$4-Inputs!$B$9/(1+Inputs!$B$4)))) -> 304.25767 | S5: =IFERROR(P5/O5,0) -> 0.44175205
A6: CH970-GREY | B6: =VLOOKUP(A6,'SKU-ASIN'!$A$4:$I$9,2,FALSE()) -> B0D8PFB4VR | C6: RRP B2C | D6: Купон | E6: =E5 -> 415.99 | F6: =E6*(1-Inputs!$B$14) -> 374.391 | G6: =F6/(1+Inputs!$B$4) -> 314.61429 | H6: =F6*Inputs!$B$15 -> 9.359775 | I6: =0 -> 0 | J6: =MAX(Inputs!$B$26,IF(F6<=Inputs!$B$23,F6*Inputs!$B$24,Inputs!$B$23*Inputs!$B$24+(F6-Inputs!$B$23)*Inputs!$B$25)) -> 47.4391 | K6: ='SKU-ASIN'!$D$4 -> 16.85 | L6: ='SKU-ASIN'!$E$4 -> 0 | M6: =F6*'SKU-ASIN'!$I$4 -> 56.15865 | N6: =G6*Inputs!$B$9 -> 25.169143 | O6: ='SKU-ASIN'!$H$4 -> 132.31 | P6: =G6-J6-K6-L6-M6-N6-I6-H6-O6 -> 27.327618 | Q6: =IFERROR(P6/G6,0) -> 0.086860702 | R6: =IF(((K6+L6+O6)/(1/(1+Inputs!$B$4)-Inputs!$B$24-'SKU-ASIN'!$I$4-Inputs!$B$9/(1+Inputs!$B$4)))<=Inputs!$B$23,((K6+L6+O6)/(1/(1+Inputs!$B$4)-Inputs!$B$24-'SKU-ASIN'!$I$4-Inputs!$B$9/(1+Inputs!$B$4))),((K6+L6+O6+Inputs!$B$23*(Inputs!$B$24-Inputs!$B$25))/(1/(1+Inputs!$B$4)-Inputs!$B$25-'SKU-ASIN'!$I$4-Inputs!$B$9/(1+Inputs!$B$4)))) -> 304.25767 | S6: =IFERROR(P6/O6,0) -> 0.20654235
A7: CH970-GREY | B7: =VLOOKUP(A7,'SKU-ASIN'!$A$4:$I$9,2,FALSE()) -> B0D8PFB4VR | C7: RRP B2C | D7: Deal | E7: =E5 -> 415.99 | F7: =E7*(1-Inputs!$B$17) -> 353.5915 | G7: =F7/(1+Inputs!$B$4) -> 297.13571 | H7: =0 -> 0 | I7: =F7*Inputs!$B$18 -> 5.3038725 | J7: =MAX(Inputs!$B$26,IF(F7<=Inputs!$B$23,F7*Inputs!$B$24,Inputs!$B$23*Inputs!$B$24+(F7-Inputs!$B$23)*Inputs!$B$25)) -> 45.35915 | K7: ='SKU-ASIN'!$D$4 -> 16.85 | L7: ='SKU-ASIN'!$E$4 -> 0 | M7: =F7*'SKU-ASIN'!$I$4 -> 53.038725 | N7: =G7*Inputs!$B$9 -> 23.770857 | O7: ='SKU-ASIN'!$H$4 -> 132.31 | P7: =G7-J7-K7-L7-M7-N7-I7-H7-O7 -> 20.50311 | Q7: =IFERROR(P7/G7,0) -> 0.069002508 | R7: =IF(((K7+L7+O7)/(1/(1+Inputs!$B$4)-Inputs!$B$24-'SKU-ASIN'!$I$4-Inputs!$B$9/(1+Inputs!$B$4)))<=Inputs!$B$23,((K7+L7+O7)/(1/(1+Inputs!$B$4)-Inputs!$B$24-'SKU-ASIN'!$I$4-Inputs!$B$9/(1+Inputs!$B$4))),((K7+L7+O7+Inputs!$B$23*(Inputs!$B$24-Inputs!$B$25))/(1/(1+Inputs!$B$4)-Inputs!$B$25-'SKU-ASIN'!$I$4-Inputs!$B$9/(1+Inputs!$B$4)))) -> 304.25767 | S7: =IFERROR(P7/O7,0) -> 0.15496266
A8: CH970-GREY | B8: =VLOOKUP(A8,'SKU-ASIN'!$A$4:$I$9,2,FALSE()) -> B0D8PFB4VR | C8: RRP B2C | D8: Prime Excl. | E8: =E5 -> 415.99 | F8: =E8*(1-Inputs!$B$20) -> 332.792 | G8: =F8/(1+Inputs!$B$4) -> 279.65714 | H8: =0 -> 0 | I8: =0 -> 0 | J8: =MAX(Inputs!$B$26,IF(F8<=Inputs!$B$23,F8*Inputs!$B$24,Inputs!$B$23*Inputs!$B$24+(F8-Inputs!$B$23)*Inputs!$B$25)) -> 43.2792 | K8: ='SKU-ASIN'!$D$4 -> 16.85 | L8: ='SKU-ASIN'!$E$4 -> 0 | M8: =F8*'SKU-ASIN'!$I$4 -> 49.9188 | N8: =G8*Inputs!$B$9 -> 22.372571 | O8: ='SKU-ASIN'!$H$4 -> 132.31 | P8: =G8-J8-K8-L8-M8-N8-I8-H8-O8 -> 14.926571 | Q8: =IFERROR(P8/G8,0) -> 0.05337454 | R8: =IF(((K8+L8+O8)/(1/(1+Inputs!$B$4)-Inputs!$B$24-'SKU-ASIN'!$I$4-Inputs!$B$9/(1+Inputs!$B$4)))<=Inputs!$B$23,((K8+L8+O8)/(1/(1+Inputs!$B$4)-Inputs!$B$24-'SKU-ASIN'!$I$4-Inputs!$B$9/(1+Inputs!$B$4))),((K8+L8+O8+Inputs!$B$23*(Inputs!$B$24-Inputs!$B$25))/(1/(1+Inputs!$B$4)-Inputs!$B$25-'SKU-ASIN'!$I$4-Inputs!$B$9/(1+Inputs!$B$4)))) -> 304.25767 | S8: =IFERROR(P8/O8,0) -> 0.11281514
A9: CH970-GREY | B9: =VLOOKUP(A9,'SKU-ASIN'!$A$4:$I$9,2,FALSE()) -> B0D8PFB4VR | C9: Business (B2B) | D9: Базовый | E9: =E5 -> 415.99 | F9: =E9/(1+Inputs!$B$4)*(1-Inputs!$B$10) -> 349.57143 | G9: =F9 -> 349.57143 | H9: =0 -> 0 | I9: =0 -> 0 | J9: =MAX(Inputs!$B$26,IF(F9<=Inputs!$B$23,F9*Inputs!$B$24,Inputs!$B$23*Inputs!$B$24+(F9-Inputs!$B$23)*Inputs!$B$25)) -> 44.957143 | K9: ='SKU-ASIN'!$D$4 -> 16.85 | L9: ='SKU-ASIN'!$E$4 -> 0 | M9: =F9*'SKU-ASIN'!$I$4 -> 52.435714 | N9: =G9*Inputs!$B$9 -> 27.965714 | O9: ='SKU-ASIN'!$H$4 -> 132.31 | P9: =G9-J9-K9-L9-M9-N9-I9-H9-O9 -> 75.052857 | Q9: =IFERROR(P9/G9,0) -> 0.21469963 | R9: =IF(((K9+L9+O9)/(1/(1+Inputs!$B$4)-Inputs!$B$24-'SKU-ASIN'!$I$4-Inputs!$B$9/(1+Inputs!$B$4)))<=Inputs!$B$23,((K9+L9+O9)/(1/(1+Inputs!$B$4)-Inputs!$B$24-'SKU-ASIN'!$I$4-Inputs!$B$9/(1+Inputs!$B$4))),((K9+L9+O9+Inputs!$B$23*(Inputs!$B$24-Inputs!$B$25))/(1/(1+Inputs!$B$4)-Inputs!$B$25-'SKU-ASIN'!$I$4-Inputs!$B$9/(1+Inputs!$B$4)))) -> 304.25767 | S9: =IFERROR(P9/O9,0) -> 0.56725007
A10: CH970-GREY | B10: =VLOOKUP(A10,'SKU-ASIN'!$A$4:$I$9,2,FALSE()) -> B0D8PFB4VR | C10: 2 шт | D10: Базовый | E10: =E5 -> 415.99 | F10: =E10*(1-Inputs!$B$11) -> 395.1905 | G10: =F10/(1+Inputs!$B$4) -> 332.09286 | H10: =0 -> 0 | I10: =0 -> 0 | J10: =MAX(Inputs!$B$26,IF(F10<=Inputs!$B$23,F10*Inputs!$B$24,Inputs!$B$23*Inputs!$B$24+(F10-Inputs!$B$23)*Inputs!$B$25)) -> 49.51905 | K10: ='SKU-ASIN'!$D$4 -> 16.85 | L10: ='SKU-ASIN'!$E$4 -> 0 | M10: =F10*'SKU-ASIN'!$I$4 -> 59.278575 | N10: =G10*Inputs!$B$9 -> 26.567429 | O10: ='SKU-ASIN'!$H$4 -> 132.31 | P10: =G10-J10-K10-L10-M10-N10-I10-H10-O10 -> 47.567804 | Q10: =IFERROR(P10/G10,0) -> 0.14323646 | R10: =IF(((K10+L10+O10)/(1/(1+Inputs!$B$4)-Inputs!$B$24-'SKU-ASIN'!$I$4-Inputs!$B$9/(1+Inputs!$B$4)))<=Inputs!$B$23,((K10+L10+O10)/(1/(1+Inputs!$B$4)-Inputs!$B$24-'SKU-ASIN'!$I$4-Inputs!$B$9/(1+Inputs!$B$4))),((K10+L10+O10+Inputs!$B$23*(Inputs!$B$24-Inputs!$B$25))/(1/(1+Inputs!$B$4)-Inputs!$B$25-'SKU-ASIN'!$I$4-Inputs!$B$9/(1+Inputs!$B$4)))) -> 304.25767 | S10: =IFERROR(P10/O10,0) -> 0.35951783
A11: CH970-GREY | B11: =VLOOKUP(A11,'SKU-ASIN'!$A$4:$I$9,2,FALSE()) -> B0D8PFB4VR | C11: 4 шт | D11: Базовый | E11: =E5 -> 415.99 | F11: =E11*(1-Inputs!$B$12) -> 386.8707 | G11: =F11/(1+Inputs!$B$4) -> 325.10143 | H11: =0 -> 0 | I11: =0 -> 0 | J11: =MAX(Inputs!$B$26,IF(F11<=Inputs!$B$23,F11*Inputs!$B$24,Inputs!$B$23*Inputs!$B$24+(F11-Inputs!$B$23)*Inputs!$B$25)) -> 48.68707 | K11: ='SKU-ASIN'!$D$4 -> 16.85 | L11: ='SKU-ASIN'!$E$4 -> 0 | M11: =F11*'SKU-ASIN'!$I$4 -> 58.030605 | N11: =G11*Inputs!$B$9 -> 26.008114 | O11: ='SKU-ASIN'!$H$4 -> 132.31 | P11: =G11-J11-K11-L11-M11-N11-I11-H11-O11 -> 43.215639 | Q11: =IFERROR(P11/G11,0) -> 0.13292971 | R11: =IF(((K11+L11+O11)/(1/(1+Inputs!$B$4)-Inputs!$B$24-'SKU-ASIN'!$I$4-Inputs!$B$9/(1+Inputs!$B$4)))<=Inputs!$B$23,((K11+L11+O11)/(1/(1+Inputs!$B$4)-Inputs!$B$24-'SKU-ASIN'!$I$4-Inputs!$B$9/(1+Inputs!$B$4))),((K11+L11+O11+Inputs!$B$23*(Inputs!$B$24-Inputs!$B$25))/(1/(1+Inputs!$B$4)-Inputs!$B$25-'SKU-ASIN'!$I$4-Inputs!$B$9/(1+Inputs!$B$4)))) -> 304.25767 | S11: =IFERROR(P11/O11,0) -> 0.32662413
A12: CH970-GREY | B12: =VLOOKUP(A12,'SKU-ASIN'!$A$4:$I$9,2,FALSE()) -> B0D8PFB4VR | C12: 6 шт | D12: Базовый | E12: =E5 -> 415.99 | F12: =E12*(1-Inputs!$B$13) -> 374.391 | G12: =F12/(1+Inputs!$B$4) -> 314.61429 | H12: =0 -> 0 | I12: =0 -> 0 | J12: =MAX(Inputs!$B$26,IF(F12<=Inputs!$B$23,F12*Inputs!$B$24,Inputs!$B$23*Inputs!$B$24+(F12-Inputs!$B$23)*Inputs!$B$25)) -> 47.4391 | K12: ='SKU-ASIN'!$D$4 -> 16.85 | L12: ='SKU-ASIN'!$E$4 -> 0 | M12: =F12*'SKU-ASIN'!$I$4 -> 56.15865 | N12: =G12*Inputs!$B$9 -> 25.169143 | O12: ='SKU-ASIN'!$H$4 -> 132.31 | P12: =G12-J12-K12-L12-M12-N12-I12-H12-O12 -> 36.687393 | Q12: =IFERROR(P12/G12,0) -> 0.1166107 | R12: =IF(((K12+L12+O12)/(1/(1+Inputs!$B$4)-Inputs!$B$24-'SKU-ASIN'!$I$4-Inputs!$B$9/(1+Inputs!$B$4)))<=Inputs!$B$23,((K12+L12+O12)/(1/(1+Inputs!$B$4)-Inputs!$B$24-'SKU-ASIN'!$I$4-Inputs!$B$9/(1+Inputs!$B$4))),((K12+L12+O12+Inputs!$B$23*(Inputs!$B$24-Inputs!$B$25))/(1/(1+Inputs!$B$4)-Inputs!$B$25-'SKU-ASIN'!$I$4-Inputs!$B$9/(1+Inputs!$B$4)))) -> 304.25767 | S12: =IFERROR(P12/O12,0) -> 0.2772836
A14: CH970-BLK | B14: =VLOOKUP(A14,'SKU-ASIN'!$A$4:$I$9,2,FALSE()) -> B0D8PGVY5V | C14: RRP B2C | D14: Базовый | E14: 395.99 | F14: =E14 -> 395.99 | G14: =F14/(1+Inputs!$B$4) -> 332.76471 | H14: =0 -> 0 | I14: =0 -> 0 | J14: =MAX(Inputs!$B$26,IF(F14<=Inputs!$B$23,F14*Inputs!$B$24,Inputs!$B$23*Inputs!$B$24+(F14-Inputs!$B$23)*Inputs!$B$25)) -> 49.599 | K14: ='SKU-ASIN'!$D$5 -> 15.98 | L14: ='SKU-ASIN'!$E$5 -> 5.55 | M14: =F14*'SKU-ASIN'!$I$5 -> 59.3985 | N14: =G14*Inputs!$B$9 -> 26.621176 | O14: ='SKU-ASIN'!$H$5 -> 118.99 | P14: =G14-J14-K14-L14-M14-N14-I14-H14-O14 -> 56.626029 | Q14: =IFERROR(P14/G14,0) -> 0.17016838 | R14: =IF(((K14+L14+O14)/(1/(1+Inputs!$B$4)-Inputs!$B$24-'SKU-ASIN'!$I$5-Inputs!$B$9/(1+Inputs!$B$4)))<=Inputs!$B$23,((K14+L14+O14)/(1/(1+Inputs!$B$4)-Inputs!$B$24-'SKU-ASIN'!$I$5-Inputs!$B$9/(1+Inputs!$B$4))),((K14+L14+O14+Inputs!$B$23*(Inputs!$B$24-Inputs!$B$25))/(1/(1+Inputs!$B$4)-Inputs!$B$25-'SKU-ASIN'!$I$5-Inputs!$B$9/(1+Inputs!$B$4)))) -> 287.74104 | S14: =IFERROR(P14/O14,0) -> 0.47588898
A15: CH970-BLK | B15: =VLOOKUP(A15,'SKU-ASIN'!$A$4:$I$9,2,FALSE()) -> B0D8PGVY5V | C15: RRP B2C | D15: Купон | E15: =E14 -> 395.99 | F15: =E15*(1-Inputs!$B$14) -> 356.391 | G15: =F15/(1+Inputs!$B$4) -> 299.48824 | H15: =F15*Inputs!$B$15 -> 8.909775 | I15: =0 -> 0 | J15: =MAX(Inputs!$B$26,IF(F15<=Inputs!$B$23,F15*Inputs!$B$24,Inputs!$B$23*Inputs!$B$24+(F15-Inputs!$B$23)*Inputs!$B$25)) -> 45.6391 | K15: ='SKU-ASIN'!$D$5 -> 15.98 | L15: ='SKU-ASIN'!$E$5 -> 5.55 | M15: =F15*'SKU-ASIN'!$I$5 -> 53.45865 | N15: =G15*Inputs!$B$9 -> 23.959059 | O15: ='SKU-ASIN'!$H$5 -> 118.99 | P15: =G15-J15-K15-L15-M15-N15-I15-H15-O15 -> 27.001651 | Q15: =IFERROR(P15/G15,0) -> 0.090159306 | R15: =IF(((K15+L15+O15)/(1/(1+Inputs!$B$4)-Inputs!$B$24-'SKU-ASIN'!$I$5-Inputs!$B$9/(1+Inputs!$B$4)))<=Inputs!$B$23,((K15+L15+O15)/(1/(1+Inputs!$B$4)-Inputs!$B$24-'SKU-ASIN'!$I$5-Inputs!$B$9/(1+Inputs!$B$4))),((K15+L15+O15+Inputs!$B$23*(Inputs!$B$24-Inputs!$B$25))/(1/(1+Inputs!$B$4)-Inputs!$B$25-'SKU-ASIN'!$I$5-Inputs!$B$9/(1+Inputs!$B$4)))) -> 287.74104 | S15: =IFERROR(P15/O15,0) -> 0.2269237
A16: CH970-BLK | B16: =VLOOKUP(A16,'SKU-ASIN'!$A$4:$I$9,2,FALSE()) -> B0D8PGVY5V | C16: RRP B2C | D16: Deal | E16: =E14 -> 395.99 | F16: =E16*(1-Inputs!$B$17) -> 336.5915 | G16: =F16/(1+Inputs!$B$4) -> 282.85 | H16: =0 -> 0 | I16: =F16*Inputs!$B$18 -> 5.0488725 | J16: =MAX(Inputs!$B$26,IF(F16<=Inputs!$B$23,F16*Inputs!$B$24,Inputs!$B$23*Inputs!$B$24+(F16-Inputs!$B$23)*Inputs!$B$25)) -> 43.65915 | K16: ='SKU-ASIN'!$D$5 -> 15.98 | L16: ='SKU-ASIN'!$E$5 -> 5.55 | M16: =F16*'SKU-ASIN'!$I$5 -> 50.488725 | N16: =G16*Inputs!$B$9 -> 22.628 | O16: ='SKU-ASIN'!$H$5 -> 118.99 | P16: =G16-J16-K16-L16-M16-N16-I16-H16-O16 -> 20.505253 | Q16: =IFERROR(P16/G16,0) -> 0.072495148 | R16: =IF(((K16+L16+O16)/(1/(1+Inputs!$B$4)-Inputs!$B$24-'SKU-ASIN'!$I$5-Inputs!$B$9/(1+Inputs!$B$4)))<=Inputs!$B$23,((K16+L16+O16)/(1/(1+Inputs!$B$4)-Inputs!$B$24-'SKU-ASIN'!$I$5-Inputs!$B$9/(1+Inputs!$B$4))),((K16+L16+O16+Inputs!$B$23*(Inputs!$B$24-Inputs!$B$25))/(1/(1+Inputs!$B$4)-Inputs!$B$25-'SKU-ASIN'!$I$5-Inputs!$B$9/(1+Inputs!$B$4)))) -> 287.74104 | S16: =IFERROR(P16/O16,0) -> 0.17232753
A17: CH970-BLK | B17: =VLOOKUP(A17,'SKU-ASIN'!$A$4:$I$9,2,FALSE()) -> B0D8PGVY5V | C17: RRP B2C | D17: Prime Excl. | E17: =E14 -> 395.99 | F17: =E17*(1-Inputs!$B$20) -> 316.792 | G17: =F17/(1+Inputs!$B$4) -> 266.21176 | H17: =0 -> 0 | I17: =0 -> 0 | J17: =MAX(Inputs!$B$26,IF(F17<=Inputs!$B$23,F17*Inputs!$B$24,Inputs!$B$23*Inputs!$B$24+(F17-Inputs!$B$23)*Inputs!$B$25)) -> 41.6792 | K17: ='SKU-ASIN'!$D$5 -> 15.98 | L17: ='SKU-ASIN'!$E$5 -> 5.55 | M17: =F17*'SKU-ASIN'!$I$5 -> 47.5188 | N17: =G17*Inputs!$B$9 -> 21.296941 | O17: ='SKU-ASIN'!$H$5 -> 118.99 | P17: =G17-J17-K17-L17-M17-N17-I17-H17-O17 -> 15.196824 | Q17: =IFERROR(P17/G17,0) -> 0.057085469 | R17: =IF(((K17+L17+O17)/(1/(1+Inputs!$B$4)-Inputs!$B$24-'SKU-ASIN'!$I$5-Inputs!$B$9/(1+Inputs!$B$4)))<=Inputs!$B$23,((K17+L17+O17)/(1/(1+Inputs!$B$4)-Inputs!$B$24-'SKU-ASIN'!$I$5-Inputs!$B$9/(1+Inputs!$B$4))),((K17+L17+O17+Inputs!$B$23*(Inputs!$B$24-Inputs!$B$25))/(1/(1+Inputs!$B$4)-Inputs!$B$25-'SKU-ASIN'!$I$5-Inputs!$B$9/(1+Inputs!$B$4)))) -> 287.74104 | S17: =IFERROR(P17/O17,0) -> 0.12771513
A18: CH970-BLK | B18: =VLOOKUP(A18,'SKU-ASIN'!$A$4:$I$9,2,FALSE()) -> B0D8PGVY5V | C18: Business (B2B) | D18: Базовый | E18: =E14 -> 395.99 | F18: =E18/(1+Inputs!$B$4)*(1-Inputs!$B$10) -> 332.76471 | G18: =F18 -> 332.76471 | H18: =0 -> 0 | I18: =0 -> 0 | J18: =MAX(Inputs!$B$26,IF(F18<=Inputs!$B$23,F18*Inputs!$B$24,Inputs!$B$23*Inputs!$B$24+(F18-Inputs!$B$23)*Inputs!$B$25)) -> 43.276471 | K18: ='SKU-ASIN'!$D$5 -> 15.98 | L18: ='SKU-ASIN'!$E$5 -> 5.55 | M18: =F18*'SKU-ASIN'!$I$5 -> 49.914706 | N18: =G18*Inputs!$B$9 -> 26.621176 | O18: ='SKU-ASIN'!$H$5 -> 118.99 | P18: =G18-J18-K18-L18-M18-N18-I18-H18-O18 -> 72.432353 | Q18: =IFERROR(P18/G18,0) -> 0.21766838 | R18: =IF(((K18+L18+O18)/(1/(1+Inputs!$B$4)-Inputs!$B$24-'SKU-ASIN'!$I$5-Inputs!$B$9/(1+Inputs!$B$4)))<=Inputs!$B$23,((K18+L18+O18)/(1/(1+Inputs!$B$4)-Inputs!$B$24-'SKU-ASIN'!$I$5-Inputs!$B$9/(1+Inputs!$B$4))),((K18+L18+O18+Inputs!$B$23*(Inputs!$B$24-Inputs!$B$25))/(1/(1+Inputs!$B$4)-Inputs!$B$25-'SKU-ASIN'!$I$5-Inputs!$B$9/(1+Inputs!$B$4)))) -> 287.74104 | S18: =IFERROR(P18/O18,0) -> 0.60872639
A19: CH970-BLK | B19: =VLOOKUP(A19,'SKU-ASIN'!$A$4:$I$9,2,FALSE()) -> B0D8PGVY5V | C19: 2 шт | D19: Базовый | E19: =E14 -> 395.99 | F19: =E19*(1-Inputs!$B$11) -> 376.1905 | G19: =F19/(1+Inputs!$B$4) -> 316.12647 | H19: =0 -> 0 | I19: =0 -> 0 | J19: =MAX(Inputs!$B$26,IF(F19<=Inputs!$B$23,F19*Inputs!$B$24,Inputs!$B$23*Inputs!$B$24+(F19-Inputs!$B$23)*Inputs!$B$25)) -> 47.61905 | K19: ='SKU-ASIN'!$D$5 -> 15.98 | L19: ='SKU-ASIN'!$E$5 -> 5.55 | M19: =F19*'SKU-ASIN'!$I$5 -> 56.428575 | N19: =G19*Inputs!$B$9 -> 25.290118 | O19: ='SKU-ASIN'!$H$5 -> 118.99 | P19: =G19-J19-K19-L19-M19-N19-I19-H19-O19 -> 46.268728 | Q19: =IFERROR(P19/G19,0) -> 0.14636145 | R19: =IF(((K19+L19+O19)/(1/(1+Inputs!$B$4)-Inputs!$B$24-'SKU-ASIN'!$I$5-Inputs!$B$9/(1+Inputs!$B$4)))<=Inputs!$B$23,((K19+L19+O19)/(1/(1+Inputs!$B$4)-Inputs!$B$24-'SKU-ASIN'!$I$5-Inputs!$B$9/(1+Inputs!$B$4))),((K19+L19+O19+Inputs!$B$23*(Inputs!$B$24-Inputs!$B$25))/(1/(1+Inputs!$B$4)-Inputs!$B$25-'SKU-ASIN'!$I$5-Inputs!$B$9/(1+Inputs!$B$4)))) -> 287.74104 | S19: =IFERROR(P19/O19,0) -> 0.38884552
A20: CH970-BLK | B20: =VLOOKUP(A20,'SKU-ASIN'!$A$4:$I$9,2,FALSE()) -> B0D8PGVY5V | C20: 4 шт | D20: Базовый | E20: =E14 -> 395.99 | F20: =E20*(1-Inputs!$B$12) -> 368.2707 | G20: =F20/(1+Inputs!$B$4) -> 309.47118 | H20: =0 -> 0 | I20: =0 -> 0 | J20: =MAX(Inputs!$B$26,IF(F20<=Inputs!$B$23,F20*Inputs!$B$24,Inputs!$B$23*Inputs!$B$24+(F20-Inputs!$B$23)*Inputs!$B$25)) -> 46.82707 | K20: ='SKU-ASIN'!$D$5 -> 15.98 | L20: ='SKU-ASIN'!$E$5 -> 5.55 | M20: =F20*'SKU-ASIN'!$I$5 -> 55.240605 | N20: =G20*Inputs!$B$9 -> 24.757694 | O20: ='SKU-ASIN'!$H$5 -> 118.99 | P20: =G20-J20-K20-L20-M20-N20-I20-H20-O20 -> 42.125807 | Q20: =IFERROR(P20/G20,0) -> 0.13612191 | R20: =IF(((K20+L20+O20)/(1/(1+Inputs!$B$4)-Inputs!$B$24-'SKU-ASIN'!$I$5-Inputs!$B$9/(1+Inputs!$B$4)))<=Inputs!$B$23,((K20+L20+O20)/(1/(1+Inputs!$B$4)-Inputs!$B$24-'SKU-ASIN'!$I$5-Inputs!$B$9/(1+Inputs!$B$4))),((K20+L20+O20+Inputs!$B$23*(Inputs!$B$24-Inputs!$B$25))/(1/(1+Inputs!$B$4)-Inputs!$B$25-'SKU-ASIN'!$I$5-Inputs!$B$9/(1+Inputs!$B$4)))) -> 287.74104 | S20: =IFERROR(P20/O20,0) -> 0.35402813
A21: CH970-BLK | B21: =VLOOKUP(A21,'SKU-ASIN'!$A$4:$I$9,2,FALSE()) -> B0D8PGVY5V | C21: 6 шт | D21: Базовый | E21: =E14 -> 395.99 | F21: =E21*(1-Inputs!$B$13) -> 356.391 | G21: =F21/(1+Inputs!$B$4) -> 299.48824 | H21: =0 -> 0 | I21: =0 -> 0 | J21: =MAX(Inputs!$B$26,IF(F21<=Inputs!$B$23,F21*Inputs!$B$24,Inputs!$B$23*Inputs!$B$24+(F21-Inputs!$B$23)*Inputs!$B$25)) -> 45.6391 | K21: ='SKU-ASIN'!$D$5 -> 15.98 | L21: ='SKU-ASIN'!$E$5 -> 5.55 | M21: =F21*'SKU-ASIN'!$I$5 -> 53.45865 | N21: =G21*Inputs!$B$9 -> 23.959059 | O21: ='SKU-ASIN'!$H$5 -> 118.99 | P21: =G21-J21-K21-L21-M21-N21-I21-H21-O21 -> 35.911426 | Q21: =IFERROR(P21/G21,0) -> 0.11990931 | R21: =IF(((K21+L21+O21)/(1/(1+Inputs!$B$4)-Inputs!$B$24-'SKU-ASIN'!$I$5-Inputs!$B$9/(1+Inputs!$B$4)))<=Inputs!$B$23,((K21+L21+O21)/(1/(1+Inputs!$B$4)-Inputs!$B$24-'SKU-ASIN'!$I$5-Inputs!$B$9/(1+Inputs!$B$4))),((K21+L21+O21+Inputs!$B$23*(Inputs!$B$24-Inputs!$B$25))/(1/(1+Inputs!$B$4)-Inputs!$B$25-'SKU-ASIN'!$I$5-Inputs!$B$9/(1+Inputs!$B$4)))) -> 287.74104 | S21: =IFERROR(P21/O21,0) -> 0.30180205
A23: CH975-GREY | B23: =VLOOKUP(A23,'SKU-ASIN'!$A$4:$I$9,2,FALSE()) -> B0FPCHVY23 | C23: RRP B2C | D23: Базовый | E23: 305.99 | F23: =E23 -> 305.99 | G23: =F23/(1+Inputs!$B$4) -> 257.13445 | H23: =0 -> 0 | I23: =0 -> 0 | J23: =MAX(Inputs!$B$26,IF(F23<=Inputs!$B$23,F23*Inputs!$B$24,Inputs!$B$23*Inputs!$B$24+(F23-Inputs!$B$23)*Inputs!$B$25)) -> 40.599 | K23: ='SKU-ASIN'!$D$6 -> 30.02 | L23: ='SKU-ASIN'!$E$6 -> 4.24 | M23: =F23*'SKU-ASIN'!$I$6 -> 45.8985 | N23: =G23*Inputs!$B$9 -> 20.570756 | O23: ='SKU-ASIN'!$H$6 -> 78.25 | P23: =G23-J23-K23-L23-M23-N23-I23-H23-O23 -> 37.556197 | Q23: =IFERROR(P23/G23,0) -> 0.14605665 | R23: =IF(((K23+L23+O23)/(1/(1+Inputs!$B$4)-Inputs!$B$24-'SKU-ASIN'!$I$6-Inputs!$B$9/(1+Inputs!$B$4)))<=Inputs!$B$23,((K23+L23+O23)/(1/(1+Inputs!$B$4)-Inputs!$B$24-'SKU-ASIN'!$I$6-Inputs!$B$9/(1+Inputs!$B$4))),((K23+L23+O23+Inputs!$B$23*(Inputs!$B$24-Inputs!$B$25))/(1/(1+Inputs!$B$4)-Inputs!$B$25-'SKU-ASIN'!$I$6-Inputs!$B$9/(1+Inputs!$B$4)))) -> 234.19582 | S23: =IFERROR(P23/O23,0) -> 0.47995141
A24: CH975-GREY | B24: =VLOOKUP(A24,'SKU-ASIN'!$A$4:$I$9,2,FALSE()) -> B0FPCHVY23 | C24: RRP B2C | D24: Купон | E24: =E23 -> 305.99 | F24: =E24*(1-Inputs!$B$14) -> 275.391 | G24: =F24/(1+Inputs!$B$4) -> 231.42101 | H24: =F24*Inputs!$B$15 -> 6.884775 | I24: =0 -> 0 | J24: =MAX(Inputs!$B$26,IF(F24<=Inputs!$B$23,F24*Inputs!$B$24,Inputs!$B$23*Inputs!$B$24+(F24-Inputs!$B$23)*Inputs!$B$25)) -> 37.5391 | K24: ='SKU-ASIN'!$D$6 -> 30.02 | L24: ='SKU-ASIN'!$E$6 -> 4.24 | M24: =F24*'SKU-ASIN'!$I$6 -> 41.30865 | N24: =G24*Inputs!$B$9 -> 18.513681 | O24: ='SKU-ASIN'!$H$6 -> 78.25 | P24: =G24-J24-K24-L24-M24-N24-I24-H24-O24 -> 14.664803 | Q24: =IFERROR(P24/G24,0) -> 0.063368502 | R24: =IF(((K24+L24+O24)/(1/(1+Inputs!$B$4)-Inputs!$B$24-'SKU-ASIN'!$I$6-Inputs!$B$9/(1+Inputs!$B$4)))<=Inputs!$B$23,((K24+L24+O24)/(1/(1+Inputs!$B$4)-Inputs!$B$24-'SKU-ASIN'!$I$6-Inputs!$B$9/(1+Inputs!$B$4))),((K24+L24+O24+Inputs!$B$23*(Inputs!$B$24-Inputs!$B$25))/(1/(1+Inputs!$B$4)-Inputs!$B$25-'SKU-ASIN'!$I$6-Inputs!$B$9/(1+Inputs!$B$4)))) -> 234.19582 | S24: =IFERROR(P24/O24,0) -> 0.18740962
A25: CH975-GREY | B25: =VLOOKUP(A25,'SKU-ASIN'!$A$4:$I$9,2,FALSE()) -> B0FPCHVY23 | C25: RRP B2C | D25: Deal | E25: =E23 -> 305.99 | F25: =E25*(1-Inputs!$B$17) -> 260.0915 | G25: =F25/(1+Inputs!$B$4) -> 218.56429 | H25: =0 -> 0 | I25: =F25*Inputs!$B$18 -> 3.9013725 | J25: =MAX(Inputs!$B$26,IF(F25<=Inputs!$B$23,F25*Inputs!$B$24,Inputs!$B$23*Inputs!$B$24+(F25-Inputs!$B$23)*Inputs!$B$25)) -> 36.00915 | K25: ='SKU-ASIN'!$D$6 -> 30.02 | L25: ='SKU-ASIN'!$E$6 -> 4.24 | M25: =F25*'SKU-ASIN'!$I$6 -> 39.013725 | N25: =G25*Inputs!$B$9 -> 17.485143 | O25: ='SKU-ASIN'!$H$6 -> 78.25 | P25: =G25-J25-K25-L25-M25-N25-I25-H25-O25 -> 9.6448954 | Q25: =IFERROR(P25/G25,0) -> 0.044128414 | R25: =IF(((K25+L25+O25)/(1/(1+Inputs!$B$4)-Inputs!$B$24-'SKU-ASIN'!$I$6-Inputs!$B$9/(1+Inputs!$B$4)))<=Inputs!$B$23,((K25+L25+O25)/(1/(1+Inputs!$B$4)-Inputs!$B$24-'SKU-ASIN'!$I$6-Inputs!$B$9/(1+Inputs!$B$4))),((K25+L25+O25+Inputs!$B$23*(Inputs!$B$24-Inputs!$B$25))/(1/(1+Inputs!$B$4)-Inputs!$B$25-'SKU-ASIN'!$I$6-Inputs!$B$9/(1+Inputs!$B$4)))) -> 234.19582 | S25: =IFERROR(P25/O25,0) -> 0.12325745
A26: CH975-GREY | B26: =VLOOKUP(A26,'SKU-ASIN'!$A$4:$I$9,2,FALSE()) -> B0FPCHVY23 | C26: RRP B2C | D26: Prime Excl. | E26: =E23 -> 305.99 | F26: =E26*(1-Inputs!$B$20) -> 244.792 | G26: =F26/(1+Inputs!$B$4) -> 205.70756 | H26: =0 -> 0 | I26: =0 -> 0 | J26: =MAX(Inputs!$B$26,IF(F26<=Inputs!$B$23,F26*Inputs!$B$24,Inputs!$B$23*Inputs!$B$24+(F26-Inputs!$B$23)*Inputs!$B$25)) -> 34.4792 | K26: ='SKU-ASIN'!$D$6 -> 30.02 | L26: ='SKU-ASIN'!$E$6 -> 4.24 | M26: =F26*'SKU-ASIN'!$I$6 -> 36.7188 | N26: =G26*Inputs!$B$9 -> 16.456605 | O26: ='SKU-ASIN'!$H$6 -> 78.25 | P26: =G26-J26-K26-L26-M26-N26-I26-H26-O26 -> 5.542958 | Q26: =IFERROR(P26/G26,0) -> 0.026945815 | R26: =IF(((K26+L26+O26)/(1/(1+Inputs!$B$4)-Inputs!$B$24-'SKU-ASIN'!$I$6-Inputs!$B$9/(1+Inputs!$B$4)))<=Inputs!$B$23,((K26+L26+O26)/(1/(1+Inputs!$B$4)-Inputs!$B$24-'SKU-ASIN'!$I$6-Inputs!$B$9/(1+Inputs!$B$4))),((K26+L26+O26+Inputs!$B$23*(Inputs!$B$24-Inputs!$B$25))/(1/(1+Inputs!$B$4)-Inputs!$B$25-'SKU-ASIN'!$I$6-Inputs!$B$9/(1+Inputs!$B$4)))) -> 234.19582 | S26: =IFERROR(P26/O26,0) -> 0.070836524
A27: CH975-GREY | B27: =VLOOKUP(A27,'SKU-ASIN'!$A$4:$I$9,2,FALSE()) -> B0FPCHVY23 | C27: Business (B2B) | D27: Базовый | E27: =E23 -> 305.99 | F27: =E27/(1+Inputs!$B$4)*(1-Inputs!$B$10) -> 257.13445 | G27: =F27 -> 257.13445 | H27: =0 -> 0 | I27: =0 -> 0 | J27: =MAX(Inputs!$B$26,IF(F27<=Inputs!$B$23,F27*Inputs!$B$24,Inputs!$B$23*Inputs!$B$24+(F27-Inputs!$B$23)*Inputs!$B$25)) -> 35.713445 | K27: ='SKU-ASIN'!$D$6 -> 30.02 | L27: ='SKU-ASIN'!$E$6 -> 4.24 | M27: =F27*'SKU-ASIN'!$I$6 -> 38.570168 | N27: =G27*Inputs!$B$9 -> 20.570756 | O27: ='SKU-ASIN'!$H$6 -> 78.25 | P27: =G27-J27-K27-L27-M27-N27-I27-H27-O27 -> 49.770084 | Q27: =IFERROR(P27/G27,0) -> 0.19355665 | R27: =IF(((K27+L27+O27)/(1/(1+Inputs!$B$4)-Inputs!$B$24-'SKU-ASIN'!$I$6-Inputs!$B$9/(1+Inputs!$B$4)))<=Inputs!$B$23,((K27+L27+O27)/(1/(1+Inputs!$B$4)-Inputs!$B$24-'SKU-ASIN'!$I$6-Inputs!$B$9/(1+Inputs!$B$4))),((K27+L27+O27+Inputs!$B$23*(Inputs!$B$24-Inputs!$B$25))/(1/(1+Inputs!$B$4)-Inputs!$B$25-'SKU-ASIN'!$I$6-Inputs!$B$9/(1+Inputs!$B$4)))) -> 234.19582 | S27: =IFERROR(P27/O27,0) -> 0.63603941
A28: CH975-GREY | B28: =VLOOKUP(A28,'SKU-ASIN'!$A$4:$I$9,2,FALSE()) -> B0FPCHVY23 | C28: 2 шт | D28: Базовый | E28: =E23 -> 305.99 | F28: =E28*(1-Inputs!$B$11) -> 290.6905 | G28: =F28/(1+Inputs!$B$4) -> 244.27773 | H28: =0 -> 0 | I28: =0 -> 0 | J28: =MAX(Inputs!$B$26,IF(F28<=Inputs!$B$23,F28*Inputs!$B$24,Inputs!$B$23*Inputs!$B$24+(F28-Inputs!$B$23)*Inputs!$B$25)) -> 39.06905 | K28: ='SKU-ASIN'!$D$6 -> 30.02 | L28: ='SKU-ASIN'!$E$6 -> 4.24 | M28: =F28*'SKU-ASIN'!$I$6 -> 43.603575 | N28: =G28*Inputs!$B$9 -> 19.542218 | O28: ='SKU-ASIN'!$H$6 -> 78.25 | P28: =G28-J28-K28-L28-M28-N28-I28-H28-O28 -> 29.552888 | Q28: =IFERROR(P28/G28,0) -> 0.12098069 | R28: =IF(((K28+L28+O28)/(1/(1+Inputs!$B$4)-Inputs!$B$24-'SKU-ASIN'!$I$6-Inputs!$B$9/(1+Inputs!$B$4)))<=Inputs!$B$23,((K28+L28+O28)/(1/(1+Inputs!$B$4)-Inputs!$B$24-'SKU-ASIN'!$I$6-Inputs!$B$9/(1+Inputs!$B$4))),((K28+L28+O28+Inputs!$B$23*(Inputs!$B$24-Inputs!$B$25))/(1/(1+Inputs!$B$4)-Inputs!$B$25-'SKU-ASIN'!$I$6-Inputs!$B$9/(1+Inputs!$B$4)))) -> 234.19582 | S28: =IFERROR(P28/O28,0) -> 0.37767269
A29: CH975-GREY | B29: =VLOOKUP(A29,'SKU-ASIN'!$A$4:$I$9,2,FALSE()) -> B0FPCHVY23 | C29: 4 шт | D29: Базовый | E29: =E23 -> 305.99 | F29: =E29*(1-Inputs!$B$12) -> 284.5707 | G29: =F29/(1+Inputs!$B$4) -> 239.13504 | H29: =0 -> 0 | I29: =0 -> 0 | J29: =MAX(Inputs!$B$26,IF(F29<=Inputs!$B$23,F29*Inputs!$B$24,Inputs!$B$23*Inputs!$B$24+(F29-Inputs!$B$23)*Inputs!$B$25)) -> 38.45707 | K29: ='SKU-ASIN'!$D$6 -> 30.02 | L29: ='SKU-ASIN'!$E$6 -> 4.24 | M29: =F29*'SKU-ASIN'!$I$6 -> 42.685605 | N29: =G29*Inputs!$B$9 -> 19.130803 | O29: ='SKU-ASIN'!$H$6 -> 78.25 | P29: =G29-J29-K29-L29-M29-N29-I29-H29-O29 -> 26.351564 | Q29: =IFERROR(P29/G29,0) -> 0.11019532 | R29: =IF(((K29+L29+O29)/(1/(1+Inputs!$B$4)-Inputs!$B$24-'SKU-ASIN'!$I$6-Inputs!$B$9/(1+Inputs!$B$4)))<=Inputs!$B$23,((K29+L29+O29)/(1/(1+Inputs!$B$4)-Inputs!$B$24-'SKU-ASIN'!$I$6-Inputs!$B$9/(1+Inputs!$B$4))),((K29+L29+O29+Inputs!$B$23*(Inputs!$B$24-Inputs!$B$25))/(1/(1+Inputs!$B$4)-Inputs!$B$25-'SKU-ASIN'!$I$6-Inputs!$B$9/(1+Inputs!$B$4)))) -> 234.19582 | S29: =IFERROR(P29/O29,0) -> 0.3367612
A30: CH975-GREY | B30: =VLOOKUP(A30,'SKU-ASIN'!$A$4:$I$9,2,FALSE()) -> B0FPCHVY23 | C30: 6 шт | D30: Базовый | E30: =E23 -> 305.99 | F30: =E30*(1-Inputs!$B$13) -> 275.391 | G30: =F30/(1+Inputs!$B$4) -> 231.42101 | H30: =0 -> 0 | I30: =0 -> 0 | J30: =MAX(Inputs!$B$26,IF(F30<=Inputs!$B$23,F30*Inputs!$B$24,Inputs!$B$23*Inputs!$B$24+(F30-Inputs!$B$23)*Inputs!$B$25)) -> 37.5391 | K30: ='SKU-ASIN'!$D$6 -> 30.02 | L30: ='SKU-ASIN'!$E$6 -> 4.24 | M30: =F30*'SKU-ASIN'!$I$6 -> 41.30865 | N30: =G30*Inputs!$B$9 -> 18.513681 | O30: ='SKU-ASIN'!$H$6 -> 78.25 | P30: =G30-J30-K30-L30-M30-N30-I30-H30-O30 -> 21.549578 | Q30: =IFERROR(P30/G30,0) -> 0.093118502 | R30: =IF(((K30+L30+O30)/(1/(1+Inputs!$B$4)-Inputs!$B$24-'SKU-ASIN'!$I$6-Inputs!$B$9/(1+Inputs!$B$4)))<=Inputs!$B$23,((K30+L30+O30)/(1/(1+Inputs!$B$4)-Inputs!$B$24-'SKU-ASIN'!$I$6-Inputs!$B$9/(1+Inputs!$B$4))),((K30+L30+O30+Inputs!$B$23*(Inputs!$B$24-Inputs!$B$25))/(1/(1+Inputs!$B$4)-Inputs!$B$25-'SKU-ASIN'!$I$6-Inputs!$B$9/(1+Inputs!$B$4)))) -> 234.19582 | S30: =IFERROR(P30/O30,0) -> 0.27539396
A32: CH975-BLK | B32: =VLOOKUP(A32,'SKU-ASIN'!$A$4:$I$9,2,FALSE()) -> B0FPCK6XPN | C32: RRP B2C | D32: Базовый | E32: 285.99 | F32: =E32 -> 285.99 | G32: =F32/(1+Inputs!$B$4) -> 240.32773 | H32: =0 -> 0 | I32: =0 -> 0 | J32: =MAX(Inputs!$B$26,IF(F32<=Inputs!$B$23,F32*Inputs!$B$24,Inputs!$B$23*Inputs!$B$24+(F32-Inputs!$B$23)*Inputs!$B$25)) -> 38.599 | K32: ='SKU-ASIN'!$D$7 -> 30.02 | L32: ='SKU-ASIN'!$E$7 -> 4.24 | M32: =F32*'SKU-ASIN'!$I$7 -> 42.8985 | N32: =G32*Inputs!$B$9 -> 19.226218 | O32: ='SKU-ASIN'!$H$7 -> 71.6 | P32: =G32-J32-K32-L32-M32-N32-I32-H32-O32 -> 33.744013 | Q32: =IFERROR(P32/G32,0) -> 0.14040832 | R32: =IF(((K32+L32+O32)/(1/(1+Inputs!$B$4)-Inputs!$B$24-'SKU-ASIN'!$I$7-Inputs!$B$9/(1+Inputs!$B$4)))<=Inputs!$B$23,((K32+L32+O32)/(1/(1+Inputs!$B$4)-Inputs!$B$24-'SKU-ASIN'!$I$7-Inputs!$B$9/(1+Inputs!$B$4))),((K32+L32+O32+Inputs!$B$23*(Inputs!$B$24-Inputs!$B$25))/(1/(1+Inputs!$B$4)-Inputs!$B$25-'SKU-ASIN'!$I$7-Inputs!$B$9/(1+Inputs!$B$4)))) -> 221.48337 | S32: =IFERROR(P32/O32,0) -> 0.47128509
A33: CH975-BLK | B33: =VLOOKUP(A33,'SKU-ASIN'!$A$4:$I$9,2,FALSE()) -> B0FPCK6XPN | C33: RRP B2C | D33: Купон | E33: =E32 -> 285.99 | F33: =E33*(1-Inputs!$B$14) -> 257.391 | G33: =F33/(1+Inputs!$B$4) -> 216.29496 | H33: =F33*Inputs!$B$15 -> 6.434775 | I33: =0 -> 0 | J33: =MAX(Inputs!$B$26,IF(F33<=Inputs!$B$23,F33*Inputs!$B$24,Inputs!$B$23*Inputs!$B$24+(F33-Inputs!$B$23)*Inputs!$B$25)) -> 35.7391 | K33: ='SKU-ASIN'!$D$7 -> 30.02 | L33: ='SKU-ASIN'!$E$7 -> 4.24 | M33: =F33*'SKU-ASIN'!$I$7 -> 38.60865 | N33: =G33*Inputs!$B$9 -> 17.303597 | O33: ='SKU-ASIN'!$H$7 -> 71.6 | P33: =G33-J33-K33-L33-M33-N33-I33-H33-O33 -> 12.348836 | Q33: =IFERROR(P33/G33,0) -> 0.057092576 | R33: =IF(((K33+L33+O33)/(1/(1+Inputs!$B$4)-Inputs!$B$24-'SKU-ASIN'!$I$7-Inputs!$B$9/(1+Inputs!$B$4)))<=Inputs!$B$23,((K33+L33+O33)/(1/(1+Inputs!$B$4)-Inputs!$B$24-'SKU-ASIN'!$I$7-Inputs!$B$9/(1+Inputs!$B$4))),((K33+L33+O33+Inputs!$B$23*(Inputs!$B$24-Inputs!$B$25))/(1/(1+Inputs!$B$4)-Inputs!$B$25-'SKU-ASIN'!$I$7-Inputs!$B$9/(1+Inputs!$B$4)))) -> 221.48337 | S33: =IFERROR(P33/O33,0) -> 0.17246978
A34: CH975-BLK | B34: =VLOOKUP(A34,'SKU-ASIN'!$A$4:$I$9,2,FALSE()) -> B0FPCK6XPN | C34: RRP B2C | D34: Deal | E34: =E32 -> 285.99 | F34: =E34*(1-Inputs!$B$17) -> 243.0915 | G34: =F34/(1+Inputs!$B$4) -> 204.27857 | H34: =0 -> 0 | I34: =F34*Inputs!$B$18 -> 3.6463725 | J34: =MAX(Inputs!$B$26,IF(F34<=Inputs!$B$23,F34*Inputs!$B$24,Inputs!$B$23*Inputs!$B$24+(F34-Inputs!$B$23)*Inputs!$B$25)) -> 34.30915 | K34: ='SKU-ASIN'!$D$7 -> 30.02 | L34: ='SKU-ASIN'!$E$7 -> 4.24 | M34: =F34*'SKU-ASIN'!$I$7 -> 36.463725 | N34: =G34*Inputs!$B$9 -> 16.342286 | O34: ='SKU-ASIN'!$H$7 -> 71.6 | P34: =G34-J34-K34-L34-M34-N34-I34-H34-O34 -> 7.6570382 | Q34: =IFERROR(P34/G34,0) -> 0.037483316 | R34: =IF(((K34+L34+O34)/(1/(1+Inputs!$B$4)-Inputs!$B$24-'SKU-ASIN'!$I$7-Inputs!$B$9/(1+Inputs!$B$4)))<=Inputs!$B$23,((K34+L34+O34)/(1/(1+Inputs!$B$4)-Inputs!$B$24-'SKU-ASIN'!$I$7-Inputs!$B$9/(1+Inputs!$B$4))),((K34+L34+O34+Inputs!$B$23*(Inputs!$B$24-Inputs!$B$25))/(1/(1+Inputs!$B$4)-Inputs!$B$25-'SKU-ASIN'!$I$7-Inputs!$B$9/(1+Inputs!$B$4)))) -> 221.48337 | S34: =IFERROR(P34/O34,0) -> 0.10694187
A35: CH975-BLK | B35: =VLOOKUP(A35,'SKU-ASIN'!$A$4:$I$9,2,FALSE()) -> B0FPCK6XPN | C35: RRP B2C | D35: Prime Excl. | E35: =E32 -> 285.99 | F35: =E35*(1-Inputs!$B$20) -> 228.792 | G35: =F35/(1+Inputs!$B$4) -> 192.26218 | H35: =0 -> 0 | I35: =0 -> 0 | J35: =MAX(Inputs!$B$26,IF(F35<=Inputs!$B$23,F35*Inputs!$B$24,Inputs!$B$23*Inputs!$B$24+(F35-Inputs!$B$23)*Inputs!$B$25)) -> 32.8792 | K35: ='SKU-ASIN'!$D$7 -> 30.02 | L35: ='SKU-ASIN'!$E$7 -> 4.24 | M35: =F35*'SKU-ASIN'!$I$7 -> 34.3188 | N35: =G35*Inputs!$B$9 -> 15.380975 | O35: ='SKU-ASIN'!$H$7 -> 71.6 | P35: =G35-J35-K35-L35-M35-N35-I35-H35-O35 -> 3.8232101 | Q35: =IFERROR(P35/G35,0) -> 0.019885398 | R35: =IF(((K35+L35+O35)/(1/(1+Inputs!$B$4)-Inputs!$B$24-'SKU-ASIN'!$I$7-Inputs!$B$9/(1+Inputs!$B$4)))<=Inputs!$B$23,((K35+L35+O35)/(1/(1+Inputs!$B$4)-Inputs!$B$24-'SKU-ASIN'!$I$7-Inputs!$B$9/(1+Inputs!$B$4))),((K35+L35+O35+Inputs!$B$23*(Inputs!$B$24-Inputs!$B$25))/(1/(1+Inputs!$B$4)-Inputs!$B$25-'SKU-ASIN'!$I$7-Inputs!$B$9/(1+Inputs!$B$4)))) -> 221.48337 | S35: =IFERROR(P35/O35,0) -> 0.053396789
A36: CH975-BLK | B36: =VLOOKUP(A36,'SKU-ASIN'!$A$4:$I$9,2,FALSE()) -> B0FPCK6XPN | C36: Business (B2B) | D36: Базовый | E36: =E32 -> 285.99 | F36: =E36/(1+Inputs!$B$4)*(1-Inputs!$B$10) -> 240.32773 | G36: =F36 -> 240.32773 | H36: =0 -> 0 | I36: =0 -> 0 | J36: =MAX(Inputs!$B$26,IF(F36<=Inputs!$B$23,F36*Inputs!$B$24,Inputs!$B$23*Inputs!$B$24+(F36-Inputs!$B$23)*Inputs!$B$25)) -> 34.032773 | K36: ='SKU-ASIN'!$D$7 -> 30.02 | L36: ='SKU-ASIN'!$E$7 -> 4.24 | M36: =F36*'SKU-ASIN'!$I$7 -> 36.04916 | N36: =G36*Inputs!$B$9 -> 19.226218 | O36: ='SKU-ASIN'!$H$7 -> 71.6 | P36: =G36-J36-K36-L36-M36-N36-I36-H36-O36 -> 45.15958 | Q36: =IFERROR(P36/G36,0) -> 0.18790832 | R36: =IF(((K36+L36+O36)/(1/(1+Inputs!$B$4)-Inputs!$B$24-'SKU-ASIN'!$I$7-Inputs!$B$9/(1+Inputs!$B$4)))<=Inputs!$B$23,((K36+L36+O36)/(1/(1+Inputs!$B$4)-Inputs!$B$24-'SKU-ASIN'!$I$7-Inputs!$B$9/(1+Inputs!$B$4))),((K36+L36+O36+Inputs!$B$23*(Inputs!$B$24-Inputs!$B$25))/(1/(1+Inputs!$B$4)-Inputs!$B$25-'SKU-ASIN'!$I$7-Inputs!$B$9/(1+Inputs!$B$4)))) -> 221.48337 | S36: =IFERROR(P36/O36,0) -> 0.63072039
A37: CH975-BLK | B37: =VLOOKUP(A37,'SKU-ASIN'!$A$4:$I$9,2,FALSE()) -> B0FPCK6XPN | C37: 2 шт | D37: Базовый | E37: =E32 -> 285.99 | F37: =E37*(1-Inputs!$B$11) -> 271.6905 | G37: =F37/(1+Inputs!$B$4) -> 228.31134 | H37: =0 -> 0 | I37: =0 -> 0 | J37: =MAX(Inputs!$B$26,IF(F37<=Inputs!$B$23,F37*Inputs!$B$24,Inputs!$B$23*Inputs!$B$24+(F37-Inputs!$B$23)*Inputs!$B$25)) -> 37.16905 | K37: ='SKU-ASIN'!$D$7 -> 30.02 | L37: ='SKU-ASIN'!$E$7 -> 4.24 | M37: =F37*'SKU-ASIN'!$I$7 -> 40.753575 | N37: =G37*Inputs!$B$9 -> 18.264908 | O37: ='SKU-ASIN'!$H$7 -> 71.6 | P37: =G37-J37-K37-L37-M37-N37-I37-H37-O37 -> 26.263812 | Q37: =IFERROR(P37/G37,0) -> 0.11503507 | R37: =IF(((K37+L37+O37)/(1/(1+Inputs!$B$4)-Inputs!$B$24-'SKU-ASIN'!$I$7-Inputs!$B$9/(1+Inputs!$B$4)))<=Inputs!$B$23,((K37+L37+O37)/(1/(1+Inputs!$B$4)-Inputs!$B$24-'SKU-ASIN'!$I$7-Inputs!$B$9/(1+Inputs!$B$4))),((K37+L37+O37+Inputs!$B$23*(Inputs!$B$24-Inputs!$B$25))/(1/(1+Inputs!$B$4)-Inputs!$B$25-'SKU-ASIN'!$I$7-Inputs!$B$9/(1+Inputs!$B$4)))) -> 221.48337 | S37: =IFERROR(P37/O37,0) -> 0.36681302
A38: CH975-BLK | B38: =VLOOKUP(A38,'SKU-ASIN'!$A$4:$I$9,2,FALSE()) -> B0FPCK6XPN | C38: 4 шт | D38: Базовый | E38: =E32 -> 285.99 | F38: =E38*(1-Inputs!$B$12) -> 265.9707 | G38: =F38/(1+Inputs!$B$4) -> 223.50479 | H38: =0 -> 0 | I38: =0 -> 0 | J38: =MAX(Inputs!$B$26,IF(F38<=Inputs!$B$23,F38*Inputs!$B$24,Inputs!$B$23*Inputs!$B$24+(F38-Inputs!$B$23)*Inputs!$B$25)) -> 36.59707 | K38: ='SKU-ASIN'!$D$7 -> 30.02 | L38: ='SKU-ASIN'!$E$7 -> 4.24 | M38: =F38*'SKU-ASIN'!$I$7 -> 39.895605 | N38: =G38*Inputs!$B$9 -> 17.880383 | O38: ='SKU-ASIN'!$H$7 -> 71.6 | P38: =G38-J38-K38-L38-M38-N38-I38-H38-O38 -> 23.271732 | Q38: =IFERROR(P38/G38,0) -> 0.10412185 | R38: =IF(((K38+L38+O38)/(1/(1+Inputs!$B$4)-Inputs!$B$24-'SKU-ASIN'!$I$7-Inputs!$B$9/(1+Inputs!$B$4)))<=Inputs!$B$23,((K38+L38+O38)/(1/(1+Inputs!$B$4)-Inputs!$B$24-'SKU-ASIN'!$I$7-Inputs!$B$9/(1+Inputs!$B$4))),((K38+L38+O38+Inputs!$B$23*(Inputs!$B$24-Inputs!$B$25))/(1/(1+Inputs!$B$4)-Inputs!$B$25-'SKU-ASIN'!$I$7-Inputs!$B$9/(1+Inputs!$B$4)))) -> 221.48337 | S38: =IFERROR(P38/O38,0) -> 0.32502419
A39: CH975-BLK | B39: =VLOOKUP(A39,'SKU-ASIN'!$A$4:$I$9,2,FALSE()) -> B0FPCK6XPN | C39: 6 шт | D39: Базовый | E39: =E32 -> 285.99 | F39: =E39*(1-Inputs!$B$13) -> 257.391 | G39: =F39/(1+Inputs!$B$4) -> 216.29496 | H39: =0 -> 0 | I39: =0 -> 0 | J39: =MAX(Inputs!$B$26,IF(F39<=Inputs!$B$23,F39*Inputs!$B$24,Inputs!$B$23*Inputs!$B$24+(F39-Inputs!$B$23)*Inputs!$B$25)) -> 35.7391 | K39: ='SKU-ASIN'!$D$7 -> 30.02 | L39: ='SKU-ASIN'!$E$7 -> 4.24 | M39: =F39*'SKU-ASIN'!$I$7 -> 38.60865 | N39: =G39*Inputs!$B$9 -> 17.303597 | O39: ='SKU-ASIN'!$H$7 -> 71.6 | P39: =G39-J39-K39-L39-M39-N39-I39-H39-O39 -> 18.783611 | Q39: =IFERROR(P39/G39,0) -> 0.086842576 | R39: =IF(((K39+L39+O39)/(1/(1+Inputs!$B$4)-Inputs!$B$24-'SKU-ASIN'!$I$7-Inputs!$B$9/(1+Inputs!$B$4)))<=Inputs!$B$23,((K39+L39+O39)/(1/(1+Inputs!$B$4)-Inputs!$B$24-'SKU-ASIN'!$I$7-Inputs!$B$9/(1+Inputs!$B$4))),((K39+L39+O39+Inputs!$B$23*(Inputs!$B$24-Inputs!$B$25))/(1/(1+Inputs!$B$4)-Inputs!$B$25-'SKU-ASIN'!$I$7-Inputs!$B$9/(1+Inputs!$B$4)))) -> 221.48337 | S39: =IFERROR(P39/O39,0) -> 0.26234094
A41: CH980-GREY | B41: =VLOOKUP(A41,'SKU-ASIN'!$A$4:$I$9,2,FALSE()) -> B0FPCK3ZQ2 | C41: RRP B2C | D41: Базовый | E41: 265.99 | F41: =E41 -> 265.99 | G41: =F41/(1+Inputs!$B$4) -> 223.52101 | H41: =0 -> 0 | I41: =0 -> 0 | J41: =MAX(Inputs!$B$26,IF(F41<=Inputs!$B$23,F41*Inputs!$B$24,Inputs!$B$23*Inputs!$B$24+(F41-Inputs!$B$23)*Inputs!$B$25)) -> 36.599 | K41: ='SKU-ASIN'!$D$8 -> 32.64 | L41: ='SKU-ASIN'!$E$8 -> 4.73 | M41: =F41*'SKU-ASIN'!$I$8 -> 39.8985 | N41: =G41*Inputs!$B$9 -> 17.881681 | O41: ='SKU-ASIN'!$H$8 -> 62.45 | P41: =G41-J41-K41-L41-M41-N41-I41-H41-O41 -> 29.321828 | Q41: =IFERROR(P41/G41,0) -> 0.13118153 | R41: =IF(((K41+L41+O41)/(1/(1+Inputs!$B$4)-Inputs!$B$24-'SKU-ASIN'!$I$8-Inputs!$B$9/(1+Inputs!$B$4)))<=Inputs!$B$23,((K41+L41+O41)/(1/(1+Inputs!$B$4)-Inputs!$B$24-'SKU-ASIN'!$I$8-Inputs!$B$9/(1+Inputs!$B$4))),((K41+L41+O41+Inputs!$B$23*(Inputs!$B$24-Inputs!$B$25))/(1/(1+Inputs!$B$4)-Inputs!$B$25-'SKU-ASIN'!$I$8-Inputs!$B$9/(1+Inputs!$B$4)))) -> 209.93703 | S41: =IFERROR(P41/O41,0) -> 0.46952486
A42: CH980-GREY | B42: =VLOOKUP(A42,'SKU-ASIN'!$A$4:$I$9,2,FALSE()) -> B0FPCK3ZQ2 | C42: RRP B2C | D42: Купон | E42: =E41 -> 265.99 | F42: =E42*(1-Inputs!$B$14) -> 239.391 | G42: =F42/(1+Inputs!$B$4) -> 201.16891 | H42: =F42*Inputs!$B$15 -> 5.984775 | I42: =0 -> 0 | J42: =MAX(Inputs!$B$26,IF(F42<=Inputs!$B$23,F42*Inputs!$B$24,Inputs!$B$23*Inputs!$B$24+(F42-Inputs!$B$23)*Inputs!$B$25)) -> 33.9391 | K42: ='SKU-ASIN'!$D$8 -> 32.64 | L42: ='SKU-ASIN'!$E$8 -> 4.73 | M42: =F42*'SKU-ASIN'!$I$8 -> 35.90865 | N42: =G42*Inputs!$B$9 -> 16.093513 | O42: ='SKU-ASIN'!$H$8 -> 62.45 | P42: =G42-J42-K42-L42-M42-N42-I42-H42-O42 -> 9.42287 | Q42: =IFERROR(P42/G42,0) -> 0.046840588 | R42: =IF(((K42+L42+O42)/(1/(1+Inputs!$B$4)-Inputs!$B$24-'SKU-ASIN'!$I$8-Inputs!$B$9/(1+Inputs!$B$4)))<=Inputs!$B$23,((K42+L42+O42)/(1/(1+Inputs!$B$4)-Inputs!$B$24-'SKU-ASIN'!$I$8-Inputs!$B$9/(1+Inputs!$B$4))),((K42+L42+O42+Inputs!$B$23*(Inputs!$B$24-Inputs!$B$25))/(1/(1+Inputs!$B$4)-Inputs!$B$25-'SKU-ASIN'!$I$8-Inputs!$B$9/(1+Inputs!$B$4)))) -> 209.93703 | S42: =IFERROR(P42/O42,0) -> 0.15088663
A43: CH980-GREY | B43: =VLOOKUP(A43,'SKU-ASIN'!$A$4:$I$9,2,FALSE()) -> B0FPCK3ZQ2 | C43: RRP B2C | D43: Deal | E43: =E41 -> 265.99 | F43: =E43*(1-Inputs!$B$17) -> 226.0915 | G43: =F43/(1+Inputs!$B$4) -> 189.99286 | H43: =0 -> 0 | I43: =F43*Inputs!$B$18 -> 3.3913725 | J43: =MAX(Inputs!$B$26,IF(F43<=Inputs!$B$23,F43*Inputs!$B$24,Inputs!$B$23*Inputs!$B$24+(F43-Inputs!$B$23)*Inputs!$B$25)) -> 32.60915 | K43: ='SKU-ASIN'!$D$8 -> 32.64 | L43: ='SKU-ASIN'!$E$8 -> 4.73 | M43: =F43*'SKU-ASIN'!$I$8 -> 33.913725 | N43: =G43*Inputs!$B$9 -> 15.199429 | O43: ='SKU-ASIN'!$H$8 -> 62.45 | P43: =G43-J43-K43-L43-M43-N43-I43-H43-O43 -> 5.0591811 | Q43: =IFERROR(P43/G43,0) -> 0.02662827 | R43: =IF(((K43+L43+O43)/(1/(1+Inputs!$B$4)-Inputs!$B$24-'SKU-ASIN'!$I$8-Inputs!$B$9/(1+Inputs!$B$4)))<=Inputs!$B$23,((K43+L43+O43)/(1/(1+Inputs!$B$4)-Inputs!$B$24-'SKU-ASIN'!$I$8-Inputs!$B$9/(1+Inputs!$B$4))),((K43+L43+O43+Inputs!$B$23*(Inputs!$B$24-Inputs!$B$25))/(1/(1+Inputs!$B$4)-Inputs!$B$25-'SKU-ASIN'!$I$8-Inputs!$B$9/(1+Inputs!$B$4)))) -> 209.93703 | S43: =IFERROR(P43/O43,0) -> 0.081011707
A44: CH980-GREY | B44: =VLOOKUP(A44,'SKU-ASIN'!$A$4:$I$9,2,FALSE()) -> B0FPCK3ZQ2 | C44: RRP B2C | D44: Prime Excl. | E44: =E41 -> 265.99 | F44: =E44*(1-Inputs!$B$20) -> 212.792 | G44: =F44/(1+Inputs!$B$4) -> 178.81681 | H44: =0 -> 0 | I44: =0 -> 0 | J44: =MAX(Inputs!$B$26,IF(F44<=Inputs!$B$23,F44*Inputs!$B$24,Inputs!$B$23*Inputs!$B$24+(F44-Inputs!$B$23)*Inputs!$B$25)) -> 31.2792 | K44: ='SKU-ASIN'!$D$8 -> 32.64 | L44: ='SKU-ASIN'!$E$8 -> 4.73 | M44: =F44*'SKU-ASIN'!$I$8 -> 31.9188 | N44: =G44*Inputs!$B$9 -> 14.305345 | O44: ='SKU-ASIN'!$H$8 -> 62.45 | P44: =G44-J44-K44-L44-M44-N44-I44-H44-O44 -> 1.4934622 | Q44: =IFERROR(P44/G44,0) -> 0.0083519117 | R44: =IF(((K44+L44+O44)/(1/(1+Inputs!$B$4)-Inputs!$B$24-'SKU-ASIN'!$I$8-Inputs!$B$9/(1+Inputs!$B$4)))<=Inputs!$B$23,((K44+L44+O44)/(1/(1+Inputs!$B$4)-Inputs!$B$24-'SKU-ASIN'!$I$8-Inputs!$B$9/(1+Inputs!$B$4))),((K44+L44+O44+Inputs!$B$23*(Inputs!$B$24-Inputs!$B$25))/(1/(1+Inputs!$B$4)-Inputs!$B$25-'SKU-ASIN'!$I$8-Inputs!$B$9/(1+Inputs!$B$4)))) -> 209.93703 | S44: =IFERROR(P44/O44,0) -> 0.023914527
A45: CH980-GREY | B45: =VLOOKUP(A45,'SKU-ASIN'!$A$4:$I$9,2,FALSE()) -> B0FPCK3ZQ2 | C45: Business (B2B) | D45: Базовый | E45: =E41 -> 265.99 | F45: =E45/(1+Inputs!$B$4)*(1-Inputs!$B$10) -> 223.52101 | G45: =F45 -> 223.52101 | H45: =0 -> 0 | I45: =0 -> 0 | J45: =MAX(Inputs!$B$26,IF(F45<=Inputs!$B$23,F45*Inputs!$B$24,Inputs!$B$23*Inputs!$B$24+(F45-Inputs!$B$23)*Inputs!$B$25)) -> 32.352101 | K45: ='SKU-ASIN'!$D$8 -> 32.64 | L45: ='SKU-ASIN'!$E$8 -> 4.73 | M45: =F45*'SKU-ASIN'!$I$8 -> 33.528151 | N45: =G45*Inputs!$B$9 -> 17.881681 | O45: ='SKU-ASIN'!$H$8 -> 62.45 | P45: =G45-J45-K45-L45-M45-N45-I45-H45-O45 -> 39.939076 | Q45: =IFERROR(P45/G45,0) -> 0.17868153 | R45: =IF(((K45+L45+O45)/(1/(1+Inputs!$B$4)-Inputs!$B$24-'SKU-ASIN'!$I$8-Inputs!$B$9/(1+Inputs!$B$4)))<=Inputs!$B$23,((K45+L45+O45)/(1/(1+Inputs!$B$4)-Inputs!$B$24-'SKU-ASIN'!$I$8-Inputs!$B$9/(1+Inputs!$B$4))),((K45+L45+O45+Inputs!$B$23*(Inputs!$B$24-Inputs!$B$25))/(1/(1+Inputs!$B$4)-Inputs!$B$25-'SKU-ASIN'!$I$8-Inputs!$B$9/(1+Inputs!$B$4)))) -> 209.93703 | S45: =IFERROR(P45/O45,0) -> 0.63953684
...

Sheet Break-even
A1: BREAK-EVEN И ОКУПАЕМОСТЬ
A3: SKU | B3: RRP с VAT (база), € | C3: Маржа на ед без VAT, € | D3: Маржа, % | E3: BE цена с VAT, € | F3: Запас по цене, % | G3: Прогноз продаж, шт/мес | H3: BE объём, шт/мес | I3: Месячная прибыль, € | J3: Стартовые инвестиции, € | K3: Запас на складе, шт | L3: Payback, мес
A4: CH970-GREY | B4: =Calculator!E5 -> 415.99 | C4: =Calculator!P5 -> 58.448214 | D4: =Calculator!Q5 -> 0.16719963 | E4: =Calculator!R5 -> 304.25767 | F4: =IFERROR((B4-E4)/B4,0) -> 0.26859379 | G4: 10 | H4: =IF(C4<=0,"маржа<=0",(Inputs!$B$6/12+Inputs!$B$33)/6/C4) -> 0.094813276 | I4: =C4*G4 -> 584.48214 | J4: =K4*'SKU-ASIN'!$H$4+(Inputs!$B$31+Inputs!$B$32)/6 -> 6615.5 | K4: 50 | L4: =IF(I4<=0,"маржа<=0",J4/I4) -> 11.318566
A5: CH970-BLK | B5: =Calculator!E14 -> 395.99 | C5: =Calculator!P14 -> 56.626029 | D5: =Calculator!Q14 -> 0.17016838 | E5: =Calculator!R14 -> 287.74104 | F5: =IFERROR((B5-E5)/B5,0) -> 0.27336285 | G5: 10 | H5: =IF(C5<=0,"маржа<=0",(Inputs!$B$6/12+Inputs!$B$33)/6/C5) -> 0.097864299 | I5: =C5*G5 -> 566.26029 | J5: =K5*'SKU-ASIN'!$H$5+(Inputs!$B$31+Inputs!$B$32)/6 -> 5949.5 | K5: 50 | L5: =IF(I5<=0,"маржа<=0",J5/I5) -> 10.506652
A6: CH975-GREY | B6: =Calculator!E23 -> 305.99 | C6: =Calculator!P23 -> 37.556197 | D6: =Calculator!Q23 -> 0.14605665 | E6: =Calculator!R23 -> 234.19582 | F6: =IFERROR((B6-E6)/B6,0) -> 0.23462916 | G6: 10 | H6: =IF(C6<=0,"маржа<=0",(Inputs!$B$6/12+Inputs!$B$33)/6/C6) -> 0.14755665 | I6: =C6*G6 -> 375.56197 | J6: =K6*'SKU-ASIN'!$H$6+(Inputs!$B$31+Inputs!$B$32)/6 -> 3912.5 | K6: 50 | L6: =IF(I6<=0,"маржа<=0",J6/I6) -> 10.417721
A7: CH975-BLK | B7: =Calculator!E32 -> 285.99 | C7: =Calculator!P32 -> 33.744013 | D7: =Calculator!Q32 -> 0.14040832 | E7: =Calculator!R32 -> 221.48337 | F7: =IFERROR((B7-E7)/B7,0) -> 0.22555553 | G7: 10 | H7: =IF(C7<=0,"маржа<=0",(Inputs!$B$6/12+Inputs!$B$33)/6/C7) -> 0.16422667 | I7: =C7*G7 -> 337.44013 | J7: =K7*'SKU-ASIN'!$H$7+(Inputs!$B$31+Inputs!$B$32)/6 -> 3580 | K7: 50 | L7: =IF(I7<=0,"маржа<=0",J7/I7) -> 10.60929
A8: CH980-GREY | B8: =Calculator!E41 -> 265.99 | C8: =Calculator!P41 -> 29.321828 | D8: =Calculator!Q41 -> 0.13118153 | E8: =Calculator!R41 -> 209.93703 | F8: =IFERROR((B8-E8)/B8,0) -> 0.21073338 | G8: 10 | H8: =IF(C8<=0,"маржа<=0",(Inputs!$B$6/12+Inputs!$B$33)/6/C8) -> 0.18899459 | I8: =C8*G8 -> 293.21828 | J8: =K8*'SKU-ASIN'!$H$8+(Inputs!$B$31+Inputs!$B$32)/6 -> 3122.5 | K8: 50 | L8: =IF(I8<=0,"маржа<=0",J8/I8) -> 10.649063
A9: CH980-BLK | B9: =Calculator!E50 -> 255.99 | C9: =Calculator!P50 -> 28.250735 | D9: =Calculator!Q50 -> 0.13132691 | E9: =Calculator!R50 -> 201.98458 | F9: =IFERROR((B9-E9)/B9,0) -> 0.21096692 | G9: 10 | H9: =IF(C9<=0,"маржа<=0",(Inputs!$B$6/12+Inputs!$B$33)/6/C9) -> 0.19616009 | I9: =C9*G9 -> 282.50735 | J9: =K9*'SKU-ASIN'!$H$9+(Inputs!$B$31+Inputs!$B$32)/6 -> 2914.5 | K9: 50 | L9: =IF(I9<=0,"маржа<=0",J9/I9) -> 10.316546
A10: ИТОГО | G10: =SUM(G4:G9) -> 60 | H10: =SUM(H4:H9) -> 0.88961556 | I10: =SUM(I4:I9) -> 2439.4702 | J10: =SUM(J4:J9) -> 26094.5 | K10: =SUM(K4:K9) -> 300 | L10: =IF(I10<=0,"маржа<=0",J10/I10) -> 10.69679
A12: BE-цена: цена с VAT, при которой маржа = 0 в базовом сценарии (без купонов/деалов, с per-SKU TACOS).
A13: BE-объём: сколько шт/мес продать, чтобы покрыть свою долю пост.расходов (EPR/12 + OpEx, поровну на SKU).
A14: Payback = (запас на складе × Полная COGS + setup) / месячная прибыль.
A15: Запас по цене — насколько RRP выше BE (выше → больше места для скидок/рекламы).

Sheet Summary
A1: МЕСЯЧНЫЙ P&L — СВОДКА
A3: Базовый сценарий: RRP B2C / Базовый. Прогноз продаж и запас на складе — с листа Break-even. TACOS — per-SKU из SKU-ASIN. Купоны / Deals / PED — отдельные кампании ниже.
A5: SKU | B5: Прод/мес шт | C5: Цена с VAT € | D5: Выручка €/мес | E5: Прибыль €/мес | F5: Маржа %
A6: CH970-GREY | B6: ='Break-even'!G4 -> 10 | C6: =Calculator!E5 -> 415.99 | D6: =B6*C6 -> 4159.9 | E6: ='Break-even'!I4 -> 584.48214 | F6: =IFERROR(E6/(D6/(1+Inputs!$B$4)),0) -> 0.16719963
A7: CH970-BLK | B7: ='Break-even'!G5 -> 10 | C7: =Calculator!E14 -> 395.99 | D7: =B7*C7 -> 3959.9 | E7: ='Break-even'!I5 -> 566.26029 | F7: =IFERROR(E7/(D7/(1+Inputs!$B$4)),0) -> 0.17016838
A8: CH975-GREY | B8: ='Break-even'!G6 -> 10 | C8: =Calculator!E23 -> 305.99 | D8: =B8*C8 -> 3059.9 | E8: ='Break-even'!I6 -> 375.56197 | F8: =IFERROR(E8/(D8/(1+Inputs!$B$4)),0) -> 0.14605665
A9: CH975-BLK | B9: ='Break-even'!G7 -> 10 | C9: =Calculator!E32 -> 285.99 | D9: =B9*C9 -> 2859.9 | E9: ='Break-even'!I7 -> 337.44013 | F9: =IFERROR(E9/(D9/(1+Inputs!$B$4)),0) -> 0.14040832
A10: CH980-GREY | B10: ='Break-even'!G8 -> 10 | C10: =Calculator!E41 -> 265.99 | D10: =B10*C10 -> 2659.9 | E10: ='Break-even'!I8 -> 293.21828 | F10: =IFERROR(E10/(D10/(1+Inputs!$B$4)),0) -> 0.13118153
A11: CH980-BLK | B11: ='Break-even'!G9 -> 10 | C11: =Calculator!E50 -> 255.99 | D11: =B11*C11 -> 2559.9 | E11: ='Break-even'!I9 -> 282.50735 | F11: =IFERROR(E11/(D11/(1+Inputs!$B$4)),0) -> 0.13132691
A12: ИТОГО валовая | B12: =SUM(B6:B11) -> 60 | D12: =SUM(D6:D11) -> 19259.4 | E12: =SUM(E6:E11) -> 2439.4702 | F12: =IFERROR(E12/(D12/(1+Inputs!$B$4)),0) -> 0.15073001
A14: ПРОМО-КАМПАНИИ
A15: Купонных кампаний в мес, шт | B15: 0 | E15: =B15*Inputs!$B$16 -> 0
A16: Deal-кампаний в мес, шт (cap €300 каждая) | B16: 0 | E16: =B16*Inputs!$B$19 -> 0
A17: PED-кампаний в мес, шт (€100 каждая, только Prime Day/BFCM) | B17: 0 | E17: =B17*Inputs!$B$21 -> 0
A19: ПОСТОЯННЫЕ РАСХОДЫ
A20: Постоянные расходы /мес (OpEx) | E20: =Inputs!$B$33 -> 0
A21: EPR /мес | E21: =Inputs!$B$6/12 -> 33.25
A23: ПРИБЫЛЬ ДО НАЛОГОВ (operating profit) | E23: =E12-E15-E16-E17-E20-E21 -> 2406.2202
A25: НАЛОГИ
A26: Корп.налог Эстонии = ставка × доля распределяемой прибыли | E26: =MAX(0,E23)*Inputs!$B$27*Inputs!$B$28 -> 0
A27: ЧИСТАЯ ПРИБЫЛЬ /МЕС | E27: =E23-E26 -> 2406.2202
A29: VAT (НДС) — cash flow, не влияет на прибыль
A30: Output VAT (с продаж B2C) | E30: =D12*Inputs!$B$4/(1+Inputs!$B$4) -> 3075.0303
A31: Input VAT возмещаемый (Customs на COGS landed) | E31: =SUMPRODUCT('SKU-ASIN'!$F$4:$F$9,'Break-even'!$G$4:$G$9)*Inputs!$B$4*Inputs!$B$29 -> 877.325
A32: Input VAT возмещаемый (Доставка 3PL → FBA) | E32: =SUMPRODUCT('SKU-ASIN'!$G$4:$G$9,'Break-even'!$G$4:$G$9)*Inputs!$B$4*Inputs!$B$29 -> 114.266
A34: NET VAT к уплате /мес (Output − Input) | E34: =E30-E31-E32 -> 2083.4393
A36: VAT — pass-through tax: НЕ уменьшает прибыль (прибыль уже считается ex-VAT). Net VAT — это сколько перечислите в немецкую налоговую раз в квартал.
A37: Корп.налог Эстонии: 0% если прибыль остаётся в компании; 22% × доля распределяемых дивидендов.
A38: Если FBA-склад в Германии → риск 'постоянного представительства' → ~15.825% корп.налога Германии на часть прибыли (уточняйте у налогового консультанта).
A39: Купон, Deal и PED — отдельные кампании. Per-unit fee учтён в Calculator; кампанийный flat fee — здесь.
